Workbook

Sheet EEGG
A1: PROGRAMACION ACADEMICA 2026-I
A2: COORDINACION DE EEGG | K2: 75 | L2: 35 | M2: 35
K3: 40 | L3: 40 | M3: 40 | N3: 40
A4: CICLO | B4: ASIGNATURA | C4: GRUPO | D4: T/P/L | E4: DIA | F4: H.INI | G4: H.FIN | H4: TOT | I4: DOCENTE | J4: Aula | K4: SI | L4: SW | M4: CC | N4: IA | O4: TOTAL
A5: 1 | B5: ÁLGEBRA Y GEOMETRÍA ANALÍTICA | C5: G1 | D5: 1T | E5: 1LUNES | F5: 0.33333333 | G5: 0.41666667 | H5: =G5-F5 -> 0.083333333 | I5: TERREROS NAVARRO, HELLEN | K5: 20 | L5: 13 | M5: 13 | N5: 13 | O5: =SUM(K5:N5) -> 59
A6: 1 | B6: ÁLGEBRA Y GEOMETRÍA ANALÍTICA | C6: G1 | D6: 2P | E6: 5VIERNES | F6: 0.33333333 | G6: 0.5 | H6: =G6-F6 -> 0.16666667 | I6: TERREROS NAVARRO, HELLEN | K6: 20 | L6: 13 | M6: 13 | N6: 13 | O6: =SUM(K6:N6) -> 59
A7: 1 | B7: BIOLOGÍA PARA CIENCIAS E INGENIERÍA | C7: G1 | D7: 1T | E7: 3MIERCOLES | F7: 0.33333333 | G7: 0.41666667 | H7: =G7-F7 -> 0.083333333 | I7: HUAMAN TINCO BORJA | K7: 20 | L7: 13 | M7: 13 | N7: 0 | O7: =SUM(K7:N7) -> 46
A8: 1 | B8: BIOLOGÍA PARA CIENCIAS E INGENIERÍA | C8: G1 | D8: 2P | E8: 3MIERCOLES | F8: 0.41666667 | G8: 0.5 | H8: =G8-F8 -> 0.083333333 | I8: HUAMAN TINCO BORJA | K8: 20 | L8: 13 | M8: 13 | N8: 0 | O8: =SUM(K8:N8) -> 46
A9: 1 | B9: BIOLOGÍA PARA CIENCIAS E INGENIERÍA | C9: G1 | D9: 3L | E9: 3MIERCOLES | F9: 0.5 | G9: 0.58333333 | H9: =G9-F9 -> 0.083333333 | I9: HUAMAN TINCO BORJA | K9: 20 | L9: 13 | M9: 13 | N9: 0 | O9: =SUM(K9:N9) -> 46
A10: 1 | B10: CALCULO 1 | C10: G1 | D10: 1T | E10: 2MARTES | F10: 0.33333333 | G10: 0.41666667 | H10: =G10-F10 -> 0.083333333 | I10: LLERENA LUCERO TEODORO | K10: 20 | L10: 13 | M10: 13 | N10: 13 | O10: =SUM(K10:N10) -> 59
A11: 1 | B11: CALCULO 1 | C11: G1 | D11: 2P | E11: 4JUEVES | F11: 0.33333333 | G11: 0.5 | H11: =G11-F11 -> 0.16666667 | I11: LLERENA LUCERO TEODORO | K11: 20 | L11: 13 | M11: 13 | N11: 13 | O11: =SUM(K11:N11) -> 59
A12: 1 | B12: DESARROLLO PERSONAL Y LIDERAZGO | C12: G1 | D12: 1T | E12: 4JUEVES | F12: 0.58333333 | G12: 0.625 | H12: =G12-F12 -> 0.041666667 | I12: ORELLLANA MANRRIQUE YOLANDA | K12: 20 | L12: 13 | M12: 13 | N12: 13 | O12: =SUM(K12:N12) -> 59
A13: 1 | B13: DESARROLLO PERSONAL Y LIDERAZGO | C13: G1 | D13: 2P | E13: 4JUEVES | F13: 0.625 | G13: 0.70833333 | H13: =G13-F13 -> 0.083333333 | I13: ORELLLANA MANRRIQUE YOLANDA | K13: 20 | L13: 13 | M13: 13 | N13: 13 | O13: =SUM(K13:N13) -> 59
A14: 1 | B14: INTRODUCCION A LA COMPUTACION | C14: G1 | D14: 1T | E14: 3MIERCOLES | F14: 0.33333333 | G14: 66.458333 | H14: =G14-F14 -> 66.125 | I14: CUADROS VARGAS ERNESTO | K14: 0 | L14: 0 | M14: 0 | N14: 40 | O14: =SUM(K14:N14) -> 40
A15: 1 | B15: INTRODUCCION A LA COMPUTACION | C15: G1 | D15: 2P | E15: 3MIERCOLES | F15: 66.458333 | G15: 66.541667 | H15: =G15-F15 -> 0.083333333 | I15: CUADROS VARGAS ERNESTO | K15: 0 | L15: 0 | M15: 0 | N15: 40 | O15: =SUM(K15:N15) -> 40
A16: 1 | B16: MEDIO AMBIENTE Y DESARROLLO SOSTENIBLE | C16: G1 | D16: 1T | E16: 6SABADO | F16: 0.33333333 | G16: 66.416667 | H16: =G16-F16 -> 66.083333 | I16: FANOLA MERINO PETRONILA | K16: 20 | L16: 13 | M16: 13 | N16: 13 | O16: =SUM(K16:N16) -> 59
... A23: 1 | B23: REDACCIÓN Y TÉCNICAS DE COMUNICACIÓN EFECTIVA I | C23: G1 | D23: 2P | E23: 1LUNES | F23: 0.5 | G23: 0.58333333 | H23: =G23-F23 -> 0.083333333 | I23: RIOS DELGADO JHOANNA | K23: 20 | L23: 13 | M23: 13 | N23: 13 | O23: =SUM(K23:N23) -> 59
A24: 1 | B24: ÁLGEBRA Y GEOMETRÍA ANALÍTICA | C24: G2 | D24: 1T | E24: 1LUNES | F24: 0.33333333 | G24: 0.41666667 | H24: =G24-F24 -> 0.083333333 | K24: 20 | L24: 13 | M24: 13 | N24: 13 | O24: =SUM(K24:N24) -> 59
A25: 1 | B25: ÁLGEBRA Y GEOMETRÍA ANALÍTICA | C25: G2 | D25: 2P | E25: 5VIERNES | F25: 0.33333333 | G25: 0.5 | H25: =G25-F25 -> 0.16666667 | K25: 20 | L25: 13 | M25: 13 | N25: 13 | O25: =SUM(K25:N25) -> 59
A26: 1 | B26: BIOLOGÍA PARA CIENCIAS E INGENIERÍA | C26: G2 | D26: 1T | E26: 3MIERCOLES | F26: 0.33333333 | G26: 0.41666667 | H26: =G26-F26 -> 0.083333333 | I26: VILLASANTE BRAVO NAYSHA | K26: 20 | L26: 13 | M26: 13 | N26: 0 | O26: =SUM(K26:N26) -> 46
A27: 1 | B27: BIOLOGÍA PARA CIENCIAS E INGENIERÍA | C27: G2 | D27: 2P | E27: 3MIERCOLES | F27: 0.41666667 | G27: 0.5 | H27: =G27-F27 -> 0.083333333 | I27: VILLASANTE BRAVO NAYSHA | K27: 20 | L27: 13 | M27: 13 | N27: 0 | O27: =SUM(K27:N27) -> 46
A28: 1 | B28: BIOLOGÍA PARA CIENCIAS E INGENIERÍA | C28: G2 | D28: 3L | E28: 3MIERCOLES | F28: 0.5 | G28: 0.58333333 | H28: =G28-F28 -> 0.083333333 | I28: VILLASANTE BRAVO NAYSHA | K28: 20 | L28: 13 | M28: 13 | N28: 0 | O28: =SUM(K28:N28) -> 46
A29: 1 | B29: CALCULO 1 | C29: G2 | D29: 1T | E29: 2MARTES | F29: 0.58333333 | G29: 0.66666667 | H29: =G29-F29 -> 0.083333333 | I29: TERREROS NAVARRO HELLEN | K29: 20 | L29: 13 | M29: 13 | N29: 13 | O29: =SUM(K29:N29) -> 59
A30: 1 | B30: CALCULO 1 | C30: G2 | D30: 2P | E30: 4JUEVES | F30: 0.58333333 | G30: 0.75 | H30: =G30-F30 -> 0.16666667 | I30: TERREROS NAVARRO HELLEN | K30: 20 | L30: 13 | M30: 13 | N30: 13 | O30: =SUM(K30:N30) -> 59
A31: 1 | B31: DESARROLLO PERSONAL Y LIDERAZGO | C31: G2 | D31: 1T | E31: 1LUNES | F31: 0.41666667 | G31: 0.45833333 | H31: =G31-F31 -> 0.041666667 | I31: ORELLLANA MANRRIQUE YOLANDA | K31: 20 | L31: 13 | M31: 13 | N31: 13 | O31: =SUM(K31:N31) -> 59
A32: 1 | B32: DESARROLLO PERSONAL Y LIDERAZGO | C32: G2 | D32: 2P | E32: 1LUNES | F32: 0.45833333 | G32: 0.54166667 | H32: =G32-F32 -> 0.083333333 | I32: ORELLLANA MANRRIQUE YOLANDA | K32: 20 | L32: 13 | M32: 13 | N32: 13 | O32: =SUM(K32:N32) -> 59
A33: 1 | B33: MEDIO AMBIENTE Y DESARROLLO SOSTENIBLE | C33: G2 | D33: 1T | E33: 4JUEVES | F33: 0.33333333 | G33: 66.416667 | H33: =G33-F33 -> 66.083333 | I33: FANOLA MERINO PETRONILA | K33: 20 | L33: 13 | M33: 13 | N33: 13 | O33: =SUM(K33:N33) -> 59
A34: 1 | B34: MEDIO AMBIENTE Y DESARROLLO SOSTENIBLE | C34: G2 | D34: 2P | E34: 4JUEVES | F34: 0.41666667 | G34: 0.5 | H34: =G34-F34 -> 0.083333333 | I34: FANOLA MERINO PETRONILA | K34: 20 | L34: 13 | M34: 13 | N34: 13 | O34: =SUM(K34:N34) -> 59
A35: 1 | B35: METODOS DE ESTUDIOS UNIVERSITARIOS | C35: G2 | D35: 1T | E35: 6SABADO | F35: 0.33333333 | G35: 0.375 | H35: =G35-F35 -> 0.041666667 | I35: COSME FELIX MIRIAM | K35: 20 | L35: 13 | M35: 13 | N35: 13 | O35: =SUM(K35:N35) -> 59
A36: 1 | B36: METODOS DE ESTUDIOS UNIVERSITARIOS | C36: G2 | D36: 2P | E36: 6SABADO | F36: 0.375 | G36: 0.45833333 | H36: =G36-F36 -> 0.083333333 | I36: COSME FELIX MIRIAM | K36: 20 | L36: 13 | M36: 13 | N36: 13 | O36: =SUM(K36:N36) -> 59
A37: 1 | B37: PROGRAMACIÓN Y COMPUTACIÓN | C37: G2 | D37: 1T | E37: 5VIERNES | F37: 0.58333333 | G37: 0.625 | H37: =G37-F37 -> 0.041666667 | I37: DAMASO RIOS MARIA ROSA | K37: 20 | L37: 13 | M37: 13 | N37: 0 | O37: =SUM(K37:N37) -> 46
... A53: 1 | B53: METODOS DE ESTUDIOS UNIVERSITARIOS | C53: G3 | D53: 2P | E53: 6SABADO | F53: 0.5 | G53: 0.58333333 | H53: =G53-F53 -> 0.083333333 | I53: COSME FELIX MIRIAM | K53: 25 | L53: 18 | M53: 18 | N53: 0 | O53: =SUM(K53:N53) -> 61
A54: 1 | B54: PROGRAMACIÓN Y COMPUTACIÓN | C54: G3 | D54: 1T | E54: 2MARTES | F54: 0.41666667 | G54: 0.45833333 | H54: =G54-F54 -> 0.041666667 | K54: 25 | L54: 18 | M54: 18 | N54: 0 | O54: =SUM(K54:N54) -> 61
A55: 1 | B55: PROGRAMACIÓN Y COMPUTACIÓN | C55: G3 | D55: 2P | E55: 2MARTES | F55: 0.45833333 | G55: 0.54166667 | H55: =G55-F55 -> 0.083333333 | K55: 25 | L55: 18 | M55: 18 | N55: 0 | O55: =SUM(K55:N55) -> 61
A56: 1 | B56: REDACCIÓN Y TÉCNICAS DE COMUNICACIÓN EFECTIVA I | C56: G3 | D56: 1T | E56: 3MIERCOLES | F56: 0.33333333 | G56: 0.41666667 | H56: =G56-F56 -> 0.083333333 | I56: RIOS DELGADO JHOANNA | K56: 25 | L56: 18 | M56: 18 | N56: 0 | O56: =SUM(K56:N56) -> 61
A57: 1 | B57: REDACCIÓN Y TÉCNICAS DE COMUNICACIÓN EFECTIVA I | C57: G3 | D57: 2P | E57: 3MIERCOLES | F57: 0.41666667 | G57: 0.5 | H57: =G57-F57 -> 0.083333333 | I57: RIOS DELGADO JHOANNA | K57: 25 | L57: 18 | M57: 18 | N57: 0 | O57: =SUM(K57:N57) -> 61
A58: 1 | B58: ÁLGEBRA Y GEOMETRÍA ANALÍTICA | C58: G4 | D58: 1T | E58: 2MARTES | F58: 0.33333333 | G58: 0.41666667 | H58: =G58-F58 -> 0.083333333 | K58: 20 | L58: 13 | M58: 13 | N58: 13 | O58: =SUM(K58:N58) -> 59
A59: 1 | B59: ÁLGEBRA Y GEOMETRÍA ANALÍTICA | C59: G4 | D59: 2P | E59: 4JUEVES | F59: 0.33333333 | G59: 0.5 | H59: =G59-F59 -> 0.16666667 | K59: 20 | L59: 13 | M59: 13 | N59: 13 | O59: =SUM(K59:N59) -> 59
A60: 1 | B60: BIOLOGÍA PARA CIENCIAS E INGENIERÍA | C60: G4 | D60: 1T | E60: 3MIERCOLES | F60: 0.33333333 | G60: 0.41666667 | H60: =G60-F60 -> 0.083333333 | I60: ARIAS RAMIREZ ANGELA | K60: 20 | L60: 13 | M60: 13 | N60: 0 | O60: =SUM(K60:N60) -> 46
A61: 1 | B61: BIOLOGÍA PARA CIENCIAS E INGENIERÍA | C61: G4 | D61: 2P | E61: 3MIERCOLES | F61: 0.41666667 | G61: 0.5 | H61: =G61-F61 -> 0.083333333 | I61: ARIAS RAMIREZ ANGELA | K61: 20 | L61: 13 | M61: 13 | N61: 0 | O61: =SUM(K61:N61) -> 46
...

Sheet Horarios EEGG
A1: UNIVERSIDAD NACIONAL MAYOR DE SAN MARCOS
A2: FACULTAD DE INGENIERÍA DE SISTEMAS E INFORMÁTICA
A3: COORDINACION DE ESTUDIOS GENERALES
A5: HORARIOS DE ASIGNATURAS DE ESTUDIOS GENERALES 2026-1
A7: CICLO I
A8: =EEGG!B5 -> ÁLGEBRA Y GEOMETRÍA ANALÍTICA
A9: GRUPO | B9: T | C9: DIA | D9: HORARIO | F9: DOCENTE PROPUESTO
A10: G-1 | B10: T | C10: =EEGG!E5 -> 1LUNES | D10: =EEGG!F5 -> 0.33333333 | E10: =EEGG!G5 -> 0.41666667 | F10: =EEGG!I5 -> TERREROS NAVARRO, HELLEN
B11: P | C11: =EEGG!E6 -> 5VIERNES | D11: =EEGG!F6 -> 0.33333333 | E11: =EEGG!G6 -> 0.5 | F11: =EEGG!I5 -> TERREROS NAVARRO, HELLEN
A12: G-2 | B12: T | C12: =EEGG!E7 -> 3MIERCOLES | D12: =EEGG!F7 -> 0.33333333 | E12: =EEGG!G7 -> 0.41666667
B13: P | C13: =EEGG!E8 -> 3MIERCOLES | D13: =EEGG!F8 -> 0.41666667 | E13: =EEGG!G8 -> 0.5
A14: G-3 | B14: T | C14: =EEGG!E9 -> 3MIERCOLES | D14: =EEGG!F9 -> 0.5 | E14: =EEGG!G9 -> 0.58333333 | F14: =EEGG!I5 -> TERREROS NAVARRO, HELLEN
B15: P | C15: =EEGG!E10 -> 2MARTES | D15: =EEGG!F10 -> 0.33333333 | E15: =EEGG!G10 -> 0.41666667 | F15: =EEGG!I5 -> TERREROS NAVARRO, HELLEN
A16: G-4 | B16: T | C16: =EEGG!E11 -> 4JUEVES | D16: =EEGG!F11 -> 0.33333333 | E16: =EEGG!G11 -> 0.5
B17: P | C17: =EEGG!E12 -> 4JUEVES | D17: =EEGG!F12 -> 0.58333333 | E17: =EEGG!G12 -> 0.625
A18: G-5 | B18: T | C18: =EEGG!E13 -> 4JUEVES | D18: =EEGG!F13 -> 0.625 | E18: =EEGG!G13 -> 0.70833333
B19: P | C19: =EEGG!E14 -> 3MIERCOLES | D19: =EEGG!F14 -> 0.33333333 | E19: =EEGG!G14 -> 66.458333
A20: G-6 | B20: T | C20: =EEGG!E15 -> 3MIERCOLES | D20: =EEGG!F15 -> 66.458333 | E20: =EEGG!G15 -> 66.541667
B21: P | C21: =EEGG!E16 -> 6SABADO | D21: =EEGG!F16 -> 0.33333333 | E21: =EEGG!G16 -> 66.416667
A23: =EEGG!B20 -> PROGRAMACIÓN Y COMPUTACIÓN
A24: GRUPO | B24: T | C24: DIA | D24: HORARIO | F24: DOCENTE
A25: G-1 | B25: T | C25: =EEGG!E17 -> 6SABADO | D25: =EEGG!F17 -> 0.41666667 | E25: =EEGG!G17 -> 0.5
B26: P | C26: =EEGG!E18 -> 2MARTES | D26: =EEGG!F18 -> 0.58333333 | E26: =EEGG!G18 -> 0.625
B27: L | C27: =EEGG!E19 -> 2MARTES | D27: =EEGG!F19 -> 0.625 | E27: =EEGG!G19 -> 0.70833333
A28: G-2 | B28: T | C28: =EEGG!E20 -> 2MARTES | D28: =EEGG!F20 -> 0.41666667 | E28: =EEGG!G20 -> 0.45833333
B29: P | C29: =EEGG!E21 -> 2MARTES | D29: =EEGG!F21 -> 0.45833333 | E29: =EEGG!G21 -> 66.541667
B30: L | C30: =EEGG!E22 -> 1LUNES | D30: =EEGG!F22 -> 0.41666667 | E30: =EEGG!G22 -> 0.5
A31: G-3 | B31: T | C31: =EEGG!E23 -> 1LUNES | D31: =EEGG!F23 -> 0.5 | E31: =EEGG!G23 -> 0.58333333
B32: P | C32: =EEGG!E24 -> 1LUNES | D32: =EEGG!F24 -> 0.33333333 | E32: =EEGG!G24 -> 0.41666667
B33: L | C33: =EEGG!E25 -> 5VIERNES | D33: =EEGG!F25 -> 0.33333333 | E33: =EEGG!G25 -> 0.5
A34: G-4 | B34: T | C34: =EEGG!E26 -> 3MIERCOLES | D34: =EEGG!F26 -> 0.33333333 | E34: =EEGG!G26 -> 0.41666667
B35: P | C35: =EEGG!E27 -> 3MIERCOLES | D35: =EEGG!F27 -> 0.41666667 | E35: =EEGG!G27 -> 0.5
B36: L | C36: =EEGG!E28 -> 3MIERCOLES | D36: =EEGG!F28 -> 0.5 | E36: =EEGG!G28 -> 0.58333333
A37: G-5 | B37: T | C37: =EEGG!E29 -> 2MARTES | D37: =EEGG!F29 -> 0.58333333 | E37: =EEGG!G29 -> 0.66666667
B38: P | C38: =EEGG!E30 -> 4JUEVES | D38: =EEGG!F30 -> 0.58333333 | E38: =EEGG!G30 -> 0.75
B39: L | C39: =EEGG!E31 -> 1LUNES | D39: =EEGG!F31 -> 0.41666667 | E39: =EEGG!G31 -> 0.45833333
A40: G-6 | B40: T | C40: =EEGG!E32 -> 1LUNES | D40: =EEGG!F32 -> 0.45833333 | E40: =EEGG!G32 -> 0.54166667
B41: P | C41: =EEGG!E33 -> 4JUEVES | D41: =EEGG!F33 -> 0.33333333 | E41: =EEGG!G33 -> 66.416667
B42: L | C42: =EEGG!E34 -> 4JUEVES | D42: =EEGG!F34 -> 0.41666667 | E42: =EEGG!G34 -> 0.5
A44: =EEGG!B35 -> METODOS DE ESTUDIOS UNIVERSITARIOS
...

Sheet hor grupos
A2: GRUPO 1
A3: H. INI. | B3: H. FIN | C3: T | D3: LUNES | E3: T | F3: MARTES | G3: T | H3: MIERCOLES | I3: T | J3: JUEVES | K3: T | L3: VIERNES | M3: T | N3: SÁBADO
A4: 0.33333333 | B4: 0.375 | C4: T | D4: ÁLGEBRA Y GEOMETRÍA ANALÍTICA docente aula | E4: T | F4: CALCULO 1 | G4: T | H4: BIOLOGÍA PARA CIENCIAS E INGENIERÍA | I4: P | J4: CALCULO 1 | K4: P | L4: ÁLGEBRA Y GEOMETRÍA ANALÍTICA | M4: T | N4: MEDIO AMBIENTE Y DESARROLLO SOSTENIBLE
A5: 0.375 | B5: 0.41666667
A6: 0.41666667 | B6: 0.45833333 | C6: T | D6: REDACCIÓN Y TÉCNICAS DE COMUNICACIÓN EFECTIVA I | E6: T | F6: PROGRAMACIÓN Y COMPUTACIÓN | G6: P | H6: BIOLOGÍA PARA CIENCIAS E INGENIERÍA | M6: P | N6: MEDIO AMBIENTE Y DESARROLLO SOSTENIBLE
A7: 0.45833333 | B7: 0.5 | E7: P | F7: PROGRAMACIÓN Y COMPUTACIÓN
A8: 0.5 | B8: 0.54166667 | C8: P | D8: REDACCIÓN Y TÉCNICAS DE COMUNICACIÓN EFECTIVA I | G8: L | H8: BIOLOGÍA PARA CIENCIAS E INGENIERÍA
A9: 0.54166667 | B9: 0.58333333
A10: 0.58333333 | B10: 0.625 | E10: T | F10: METODOS DE ESTUDIOS UNIVERSITARIOS | I10: T | J10: DESARROLLO PERSONAL Y LIDERAZGO | K10: T | M10: T
A11: 0.625 | B11: 0.66666667 | E11: P | F11: METODOS DE ESTUDIOS UNIVERSITARIOS | I11: P | J11: DESARROLLO PERSONAL Y LIDERAZGO | K11: P | M11: P
A12: 0.66666667 | B12: 0.70833333
A13: 0.70833333 | B13: 0.75
A14: 0.75 | B14: 0.79166667
A15: 0.79166667 | B15: 0.83333333
A16: 0.83333333 | B16: 0.875
A17: 0.875 | B17: 0.91666667
A20: GRUPO 2
A21: H. INI. | B21: H. FIN | C21: T | D21: LUNES | E21: T | F21: MARTES | G21: T | H21: MIERCOLES | I21: T | J21: JUEVES | K21: T | L21: VIERNES | M21: T | N21: SÁBADO
A22: 0.33333333 | B22: 0.375 | C22: T | D22: ÁLGEBRA Y GEOMETRÍA ANALÍTICA | E22: T | F22: REDACCIÓN Y TÉCNICAS DE COMUNICACIÓN EFECTIVA I | G22: T | H22: BIOLOGÍA PARA CIENCIAS E INGENIERÍA | I22: T | J22: MEDIO AMBIENTE Y DESARROLLO SOSTENIBLE | K22: P | L22: ÁLGEBRA Y GEOMETRÍA ANALÍTICA | M22: T | N22: METODOS DE ESTUDIOS UNIVERSITARIOS
A23: 0.375 | B23: 0.41666667 | M23: P | N23: METODOS DE ESTUDIOS UNIVERSITARIOS
A24: 0.41666667 | B24: 0.45833333 | C24: T | D24: DESARROLLO PERSONAL Y LIDERAZGO | E24: P | F24: REDACCIÓN Y TÉCNICAS DE COMUNICACIÓN EFECTIVA I | G24: P | H24: BIOLOGÍA PARA CIENCIAS E INGENIERÍA | I24: P | J24: MEDIO AMBIENTE Y DESARROLLO SOSTENIBLE
A25: 0.45833333 | B25: 0.5 | C25: P | D25: DESARROLLO PERSONAL Y LIDERAZGO
A26: 0.5 | B26: 0.54166667 | G26: L | H26: BIOLOGÍA PARA CIENCIAS E INGENIERÍA
A27: 0.54166667 | B27: 0.58333333
A28: 0.58333333 | B28: 0.625 | E28: T | F28: CALCULO 1 | I28: P | J28: CALCULO 1 | K28: T | L28: PROGRAMACIÓN Y COMPUTACIÓN | M28: T
A29: 0.625 | B29: 0.66666667 | K29: P | L29: PROGRAMACIÓN Y COMPUTACIÓN | M29: P
A30: 0.66666667 | B30: 0.70833333
A31: 0.70833333 | B31: 0.75
A32: 0.75 | B32: 0.79166667
A33: 0.79166667 | B33: 0.83333333
A34: 0.83333333 | B34: 0.875
A35: 0.875 | B35: 0.91666667

Sheet P2023
A1: PROGRAMACION ACADEMICA 2025-I
A2: EP INGNIERIA DE SISTEMAS
A4: CICLO | B4: ASIGNATURA | C4: GRUPO | D4: T/P/L | E4: DIA | F4: H.INI | G4: H.FIN | H4: TOT | I4: DOCENTE | J4: P2023 | K4: P2018 | M4: TOTAL
A5: 3 | B5: ELECTROMAGNETISMO Y ÓPTICA | C5: G1 | D5: 1T | E5: 1LUNES | F5: 0.33333333 | G5: 0.45833333 | H5: =G5-F5 -> 0.125
A6: 3 | B6: ELECTROMAGNETISMO Y ÓPTICA | C6: G1 | D6: 2P | E6: 1LUNES | F6: 0.45833333 | G6: 0.54166667 | H6: =G6-F6 -> 0.083333333
A7: 3 | B7: FUNDAMENTOS DE SISTEMAS DE INFORMACIÓN | C7: G1 | D7: 1T | E7: 5VIERNES | F7: 0.58333333 | G7: 0.625 | H7: =G7-F7 -> 0.041666667
A8: 3 | B8: FUNDAMENTOS DE SISTEMAS DE INFORMACIÓN | C8: G1 | D8: 2P | E8: 5VIERNES | F8: 0.625 | G8: 0.70833333 | H8: =G8-F8 -> 0.083333333
A9: 3 | B9: INTRODUCCIÓN A LA COMPUTACIÓN | C9: G1 | D9: 1T | E9: 4JUEVES | F9: 0.33333333 | G9: 0.45833333 | H9: =G9-F9 -> 0.125
A10: 3 | B10: INTRODUCCIÓN A LA COMPUTACIÓN | C10: G1 | D10: 2P | E10: 4JUEVES | F10: 0.45833333 | G10: 0.54166667 | H10: =G10-F10 -> 0.083333333
A11: 3 | B11: MATEMÁTICAS DISCRETAS | C11: G1 | D11: 1T | E11: 2MARTES | F11: 0.33333333 | G11: 0.41666667 | H11: =G11-F11 -> 0.083333333
A12: 3 | B12: MATEMÁTICAS DISCRETAS | C12: G1 | D12: 2P | E12: 2MARTES | F12: 0.41666667 | G12: 0.58333333 | H12: =G12-F12 -> 0.16666667
A13: 3 | B13: PROGRAMACIÓN DE COMPUTADORAS I | C13: G1 | D13: 1T | E13: 3MIERCOLES | F13: 0.33333333 | G13: 0.41666667 | H13: =G13-F13 -> 0.083333333
A14: 3 | B14: PROGRAMACIÓN DE COMPUTADORAS I | C14: G1 | D14: 2P | E14: 3MIERCOLES | F14: 0.41666667 | G14: 0.5 | H14: =G14-F14 -> 0.083333333
A15: 3 | B15: PROGRAMACIÓN DE COMPUTADORAS I | C15: G1 | D15: 3L | E15: 3MIERCOLES | F15: 0.5 | G15: 0.58333333 | H15: =G15-F15 -> 0.083333333
A16: 3 | B16: SERIES Y ECUACIONES DIFERENCIALES | C16: G1 | D16: 1T | E16: 5VIERNES | F16: 0.33333333 | G16: 0.45833333 | H16: =G16-F16 -> 0.125
... A140: 6 | B140: MODELOS Y SIMULACIÓN | C140: G4 | D140: 3L | E140: 5VIERNES | F140: 0.66666667 | G140: 0.75 | H140: =G140-F140 -> 0.083333333
A149: 1LUNES
A150: 2MARTES
A151: 3MIERCOLES
A152: 4JUEVES
A153: 5VIERNES
A154: 6SABADO

Sheet PLAN 2018
A1: PROGRAMACION ACADEMICA 2025-I
A2: EP INGNIERIA DE SISTEMAS
A4: CICLO | B4: ASIGNATURA | C4: GRUPO | D4: T/P/L | E4: DIA | F4: H.INI | G4: H.FIN | H4: TOT | I4: Plan 2023
A5: 3 | B5: SERIES Y ECUACIONES DIFERENCIALES | C5: G1 | D5: 1T | E5: 5VIERNES | F5: 0.33333333 | G5: 0.45833333 | H5: =G5-F5 -> 0.125 | I5: SERIES Y ECUACIONES DIFERENCIALES
A6: 3 | B6: SERIES Y ECUACIONES DIFERENCIALES | C6: G1 | D6: 2P | E6: 5VIERNES | F6: 0.45833333 | G6: 0.54166667 | H6: =G6-F6 -> 0.083333333 | I6: SERIES Y ECUACIONES DIFERENCIALES
A7: 3 | B7: TEORIA GENERAL DE SISTEMAS | C7: G1 | D7: 1T | E7: 5VIERNES | F7: 0.58333333 | G7: 0.625 | H7: =G7-F7 -> 0.041666667 | I7: FUNDAMENTOS DE SISTEMAS DE INFORMACIÓN
A8: 3 | B8: TEORIA GENERAL DE SISTEMAS | C8: G1 | D8: 2P | E8: 5VIERNES | F8: 0.625 | G8: 0.70833333 | H8: =G8-F8 -> 0.083333333 | I8: FUNDAMENTOS DE SISTEMAS DE INFORMACIÓN
A9: 3 | B9: ORGANIZACIÓN Y ADMINISTRACIÓN | C9: G1 | D9: 1T | E9: 4JUEVES | F9: 0.33333333 | G9: 0.41666667 | H9: =G9-F9 -> 0.083333333 | I9: ORGANIZACIÓN EMPRESARIAL
A10: 3 | B10: ORGANIZACIÓN Y ADMINISTRACIÓN | C10: G1 | D10: 2P | E10: 4JUEVES | F10: 0.41666667 | G10: 0.5 | H10: =G10-F10 -> 0.083333333 | I10: ORGANIZACIÓN EMPRESARIAL
A11: 3 | B11: MATEMÁTICAS DISCRETAS | C11: G1 | D11: 1T | E11: 2MARTES | F11: 0.33333333 | G11: 0.41666667 | H11: =G11-F11 -> 0.083333333 | I11: MATEMÁTICAS DISCRETAS
A12: 3 | B12: MATEMÁTICAS DISCRETAS | C12: G1 | D12: 2P | E12: 2MARTES | F12: 0.41666667 | G12: 0.5 | H12: =G12-F12 -> 0.083333333 | I12: MATEMÁTICAS DISCRETAS
A13: 3 | B13: ESTADÍSTICA | C13: G1 | D13: 1T | E13: 5VIERNES | F13: 0.33333333 | G13: 0.45833333 | H13: =G13-F13 -> 0.125 | I13: ESTADÍSTICA I
A14: 3 | B14: ESTADÍSTICA | C14: G1 | D14: 3L | E14: 5VIERNES | F14: 0.45833333 | G14: 0.54166667 | H14: =G14-F14 -> 0.083333333 | I14: ESTADÍSTICA I
A15: 3 | B15: PROGRAMACION Y FUNDAMENTOS DE ALGORITMiCA | C15: G1 | D15: 1T | E15: 3MIERCOLES | F15: 0.33333333 | G15: 0.41666667 | H15: =G15-F15 -> 0.083333333 | I15: PROGRAMACIÓN DE COMPUTADORAS I
A16: 3 | B16: PROGRAMACION Y FUNDAMENTOS DE ALGORITMOS | C16: G1 | D16: 3L | E16: 3MIERCOLES | F16: 0.41666667 | G16: 0.5 | H16: =G16-F16 -> 0.083333333 | I16: PROGRAMACIÓN DE COMPUTADORAS I
... A21: 4 | B21: FISICA ELECTRÓNICA Y SISTEMAS DIGITALES | C21: G1 | D21: 3L | E21: 1LUNES | F21: 0.45833333 | G21: 0.54166667 | H21: =G21-F21 -> 0.083333333 | I21: ELECTROMAGNETISMO Y ÓPTICA
A22: 4 | B22: MARKETING | C22: G1 | D22: 1T | E22: 5VIERNES | F22: 0.58333333 | G22: 0.625 | H22: =G22-F22 -> 0.041666667
A23: 4 | B23: MARKETING | C23: G1 | D23: 2P | E23: 5VIERNES | F23: 0.625 | G23: 0.70833333 | H23: =G23-F23 -> 0.083333333
A24: 4 | B24: CONTABILIDAD GENERAL | C24: G1 | D24: 1T | E24: 3MIERCOLES | F24: 0.33333333 | G24: 0.41666667 | H24: =G24-F24 -> 0.083333333
A25: 4 | B25: CONTABILIDAD GENERAL | C25: G1 | D25: 2P | E25: 3MIERCOLES | F25: 0.41666667 | G25: 0.5 | H25: =G25-F25 -> 0.083333333
A26: 4 | B26: PROCESOS DE NEGOCIO | C26: G1 | D26: 1T | E26: 1LUNES | F26: 0.58333333 | G26: 0.66666667 | H26: =G26-F26 -> 0.083333333
A27: 4 | B27: PROCESOS DE NEGOCIO | C27: G1 | D27: 3L | E27: 1LUNES | F27: 0.66666667 | G27: 0.75 | H27: =G27-F27 -> 0.083333333
A28: 4 | B28: PROBABILIDADES Y MUESTREO | C28: G1 | D28: 1T | E28: 2MARTES | F28: 0.33333333 | G28: 0.41666667 | H28: =G28-F28 -> 0.083333333
A29: 4 | B29: PROBABILIDADES Y MUESTREO | C29: G1 | D29: 3L | E29: 2MARTES | F29: 0.41666667 | G29: 0.5 | H29: =G29-F29 -> 0.083333333
A30: 4 | B30: MÉTODOS NUMÉRICOS | C30: G1 | D30: 1T | E30: 5VIERNES | F30: 0.33333333 | G30: 0.41666667 | H30: =G30-F30 -> 0.083333333 | I30: MÉTODOS NUMÉRICOS
A31: 4 | B31: MÉTODOS NUMÉRICOS | C31: G1 | D31: 3L | E31: 5VIERNES | F31: 0.41666667 | G31: 0.5 | H31: =G31-F31 -> 0.083333333 | I31: MÉTODOS NUMÉRICOS
A32: 4 | B32: ALGORITMICA Y PROGRAMACIÓN ORIENTADA A OBJETOS | C32: G1 | D32: 1T | E32: 4JUEVES | F32: 0.33333333 | G32: 0.41666667 | H32: =G32-F32 -> 0.083333333 | I32: PROGRAMACIÓN DE COMPUTADORAS II
A33: 4 | B33: ALGORITMICA Y PROGRAMACIÓN ORIENTADA A OBJETOS | C33: G1 | D33: 2P | E33: 4JUEVES | F33: 0.41666667 | G33: 0.5 | H33: =G33-F33 -> 0.083333333 | I33: PROGRAMACIÓN DE COMPUTADORAS II
A34: 4 | B34: ALGORITMICA Y PROGRAMACIÓN ORIENTADA A OBJETOS | C34: G1 | D34: 3L | E34: 4JUEVES | F34: 0.5 | G34: 0.58333333 | H34: =G34-F34 -> 0.083333333 | I34: PROGRAMACIÓN DE COMPUTADORAS II
A35: 5 | B35: ARQUITECTURA DE COMPUTADORAS | C35: G1 | D35: 1T | E35: 1LUNES | F35: 0.33333333 | G35: 0.45833333 | H35: =G35-F35 -> 0.125 | I35: ARQUITECTURA DE COMPUTADORAS
A36: 5 | B36: ARQUITECTURA DE COMPUTADORAS | C36: G1 | D36: 3L | E36: 1LUNES | F36: 0.45833333 | G36: 0.54166667 | H36: =G36-F36 -> 0.083333333 | I36: ARQUITECTURA DE COMPUTADORAS
A37: 5 | B37: ANÁLISIS DE SISTEMAS DE INFORMACIÓN | C37: G1 | D37: 1T | E37: 5VIERNES | F37: 0.33333333 | G37: 0.41666667 | H37: =G37-F37 -> 0.083333333 | I37: ANÁLISIS DE SISTEMAS DE INFORMACIÓN
A38: 5 | B38: ANÁLISIS DE SISTEMAS DE INFORMACIÓN | C38: G1 | D38: 3L | E38: 5VIERNES | F38: 0.41666667 | G38: 0.5 | H38: =G38-F38 -> 0.083333333 | I38: ANÁLISIS DE SISTEMAS DE INFORMACIÓN
A39: 5 | B39: BASE DE DATOS | C39: G1 | D39: 1T | E39: 4JUEVES | F39: 0.33333333 | G39: 0.45833333 | H39: =G39-F39 -> 0.125 | I39: DISEÑO DE BASE DE DATOS
A40: 5 | B40: BASE DE DATOS | C40: G1 | D40: 3L | E40: 4JUEVES | F40: 0.45833333 | G40: 0.54166667 | H40: =G40-F40 -> 0.083333333 | I40: DISEÑO DE BASE DE DATOS
A41: 5 | B41: ESTRUCTURA DE DATOS | C41: G1 | D41: 1T | E41: 3MIERCOLES | F41: 0.33333333 | G41: 0.41666667 | H41: =G41-F41 -> 0.083333333 | I41: ESTRUCTURA DE DATOS
... A44: 5 | B44: MODELOS Y SIMULACIÓN | C44: G1 | D44: 3L | E44: 5VIERNES | F44: 0.66666667 | G44: 0.75 | H44: =G44-F44 -> 0.083333333 | I44: MODELOS Y SIMULACIÓN
A45: 5 | B45: DISEÑO Y ANALISIS DE ALGORITMOS | C45: G1 | D45: 1T | E45: 4JUEVES | F45: 0.58333333 | G45: 0.66666667 | H45: =G45-F45 -> 0.083333333
A46: 5 | B46: DISEÑO Y ANALISIS DE ALGORITMOS | C46: G1 | D46: 2P | E46: 4JUEVES | F46: 0.66666667 | G46: 0.75 | H46: =G46-F46 -> 0.083333333
A47: 5 | B47: LENGUAJES Y COMPILADORES | C47: G1 | D47: 1T | E47: 2MARTES | F47: 0.33333333 | G47: 0.41666667 | H47: =G47-F47 -> 0.083333333
...

Sheet LISTAS
A1: 1T | B1: 1LUNES
A2: 2P | B2: 2MARTES
A3: 3L | B3: 3MIERCOLES
B4: 4JUEVES
B5: 5VIERNES
B6: 6SABADO
